Traceback (most recent call last):
  File "/Users/chandrasingh/opt/anaconda3/envs/fast/lib/python3.8/site-packages/jupyter_cache/executors/utils.py", line 51, in single_nb_execution
    executenb(
  File "/Users/chandrasingh/opt/anaconda3/envs/fast/lib/python3.8/site-packages/nbclient/client.py", line 1204, in execute
    return NotebookClient(nb=nb, resources=resources, km=km, **kwargs).execute()
  File "/Users/chandrasingh/opt/anaconda3/envs/fast/lib/python3.8/site-packages/nbclient/util.py", line 84, in wrapped
    return just_run(coro(*args, **kwargs))
  File "/Users/chandrasingh/opt/anaconda3/envs/fast/lib/python3.8/site-packages/nbclient/util.py", line 62, in just_run
    return loop.run_until_complete(coro)
  File "/Users/chandrasingh/opt/anaconda3/envs/fast/lib/python3.8/asyncio/base_events.py", line 616, in run_until_complete
    return future.result()
  File "/Users/chandrasingh/opt/anaconda3/envs/fast/lib/python3.8/site-packages/nbclient/client.py", line 663, in async_execute
    await self.async_execute_cell(
  File "/Users/chandrasingh/opt/anaconda3/envs/fast/lib/python3.8/site-packages/nbclient/client.py", line 965, in async_execute_cell
    await self._check_raise_for_error(cell, cell_index, exec_reply)
  File "/Users/chandrasingh/opt/anaconda3/envs/fast/lib/python3.8/site-packages/nbclient/client.py", line 862, in _check_raise_for_error
    raise CellExecutionError.from_cell_and_msg(cell, exec_reply_content)
nbclient.exceptions.CellExecutionError: An error occurred while executing the following cell:
------------------
from sklearn.metrics import confusion_matrix, ConfusionMatrixDisplay

predictions = clf.predict(X_test)
cm = confusion_matrix(y_test, predictions, labels=clf.classes_)
disp = ConfusionMatrixDisplay(confusion_matrix=cm, # display_labels=clf.classes_, 
                              display_labels=cn)
disp.plot(cmap="Blues")
# plt.savefig('./images/iris_decision_tree_confusion_matrix.png', dpi=100)
# plt.close()
plt.show()
------------------

[0;31m---------------------------------------------------------------------------[0m
[0;31mNameError[0m                                 Traceback (most recent call last)
Input [0;32mIn [9][0m, in [0;36m<cell line: 5>[0;34m()[0m
[1;32m      3[0m predictions [38;5;241m=[39m clf[38;5;241m.[39mpredict(X_test)
[1;32m      4[0m cm [38;5;241m=[39m confusion_matrix(y_test, predictions, labels[38;5;241m=[39mclf[38;5;241m.[39mclasses_)
[1;32m      5[0m disp [38;5;241m=[39m ConfusionMatrixDisplay(confusion_matrix[38;5;241m=[39mcm, [38;5;66;03m# display_labels=clf.classes_, [39;00m
[0;32m----> 6[0m                               display_labels[38;5;241m=[39m[43mcn[49m)
[1;32m      7[0m disp[38;5;241m.[39mplot(cmap[38;5;241m=[39m[38;5;124m"[39m[38;5;124mBlues[39m[38;5;124m"[39m)
[1;32m      8[0m [38;5;66;03m# plt.savefig('./images/iris_decision_tree_confusion_matrix.png', dpi=100)[39;00m
[1;32m      9[0m [38;5;66;03m# plt.close()[39;00m

[0;31mNameError[0m: name 'cn' is not defined
NameError: name 'cn' is not defined

