Traceback (most recent call last):
  File "/Users/chandrasingh/opt/anaconda3/lib/python3.8/site-packages/jupyter_cache/executors/utils.py", line 51, in single_nb_execution
    executenb(
  File "/Users/chandrasingh/opt/anaconda3/lib/python3.8/site-packages/nbclient/client.py", line 1204, in execute
    return NotebookClient(nb=nb, resources=resources, km=km, **kwargs).execute()
  File "/Users/chandrasingh/opt/anaconda3/lib/python3.8/site-packages/nbclient/util.py", line 84, in wrapped
    return just_run(coro(*args, **kwargs))
  File "/Users/chandrasingh/opt/anaconda3/lib/python3.8/site-packages/nbclient/util.py", line 62, in just_run
    return loop.run_until_complete(coro)
  File "/Users/chandrasingh/opt/anaconda3/lib/python3.8/asyncio/base_events.py", line 616, in run_until_complete
    return future.result()
  File "/Users/chandrasingh/opt/anaconda3/lib/python3.8/site-packages/nbclient/client.py", line 663, in async_execute
    await self.async_execute_cell(
  File "/Users/chandrasingh/opt/anaconda3/lib/python3.8/site-packages/nbclient/client.py", line 965, in async_execute_cell
    await self._check_raise_for_error(cell, cell_index, exec_reply)
  File "/Users/chandrasingh/opt/anaconda3/lib/python3.8/site-packages/nbclient/client.py", line 862, in _check_raise_for_error
    raise CellExecutionError.from_cell_and_msg(cell, exec_reply_content)
nbclient.exceptions.CellExecutionError: An error occurred while executing the following cell:
------------------
def foo(pos, *, forcenamed):
    print(pos, forcenamed)

foo(pos=10, forcenamed=20)
foo(10, forcenamed=20)
assert foo(10, 20), "This should fail with TypeError"

------------------

[0;31m---------------------------------------------------------------------------[0m
[0;31mTypeError[0m                                 Traceback (most recent call last)
Input [0;32mIn [112][0m, in [0;36m<cell line: 6>[0;34m()[0m
[1;32m      4[0m foo(pos[38;5;241m=[39m[38;5;241m10[39m, forcenamed[38;5;241m=[39m[38;5;241m20[39m)
[1;32m      5[0m foo([38;5;241m10[39m, forcenamed[38;5;241m=[39m[38;5;241m20[39m)
[0;32m----> 6[0m [38;5;28;01massert[39;00m [43mfoo[49m[43m([49m[38;5;241;43m10[39;49m[43m,[49m[43m [49m[38;5;241;43m20[39;49m[43m)[49m, [38;5;124m"[39m[38;5;124mThis should fail with TypeError[39m[38;5;124m"[39m

[0;31mTypeError[0m: foo() takes 1 positional argument but 2 were given
TypeError: foo() takes 1 positional argument but 2 were given

